nohup: ignoring input
[2025-02-13 10:35:28 +0000] [1629] [INFO] Starting gunicorn 23.0.0
[2025-02-13 10:35:28 +0000] [1629] [INFO] Listening at: http://0.0.0.0:8000 (1629)
[2025-02-13 10:35:28 +0000] [1629] [INFO] Using worker: sync
[2025-02-13 10:35:28 +0000] [1630] [INFO] Booting worker with pid: 1630
[2025-02-13 10:47:40 +0000] [1629] [INFO] Handling signal: hup
[2025-02-13 10:47:40 +0000] [1629] [INFO] Hang up: Master
[2025-02-13 10:47:40 +0000] [1629] [ERROR] Worker (pid:1630) was sent SIGHUP!
[2025-02-13 10:47:40 +0000] [1752] [INFO] Booting worker with pid: 1752
[2025-02-13 10:47:40 +0000] [1629] [INFO] Handling signal: term
[2025-02-13 10:47:40 +0000] [1752] [ERROR] Exception in worker process
Traceback (most recent call last):
  File "/home/ubuntu/myenv/lib/python3.12/site-packages/gunicorn/arbiter.py", line 608, in spawn_worker
  File "/home/ubuntu/myenv/lib/python3.12/site-packages/gunicorn/workers/base.py", line 135, in init_process
  File "/home/ubuntu/myenv/lib/python3.12/site-packages/gunicorn/workers/base.py", line 147, in load_wsgi
  File "/home/ubuntu/myenv/lib/python3.12/site-packages/gunicorn/app/base.py", line 66, in wsgi
  File "/home/ubuntu/myenv/lib/python3.12/site-packages/gunicorn/app/wsgiapp.py", line 57, in load
  File "/home/ubuntu/myenv/lib/python3.12/site-packages/gunicorn/app/wsgiapp.py", line 47, in load_wsgiapp
  File "/home/ubuntu/myenv/lib/python3.12/site-packages/gunicorn/util.py", line 370, in import_app
  File "/usr/lib/python3.12/importlib/__init__.py", line 90, in import_module
    return _bootstrap._gcd_import(name[level:], package, level)
           ^^^^^^^^^^^^^^^^^^^^^^^^^^^^^^^^^^^^^^^^^^^^^^^^^^^^
  File "<frozen importlib._bootstrap>", line 1387, in _gcd_import
  File "<frozen importlib._bootstrap>", line 1360, in _find_and_load
  File "<frozen importlib._bootstrap>", line 1331, in _find_and_load_unlocked
  File "<frozen importlib._bootstrap>", line 935, in _load_unlocked
  File "<frozen importlib._bootstrap_external>", line 995, in exec_module
  File "<frozen importlib._bootstrap>", line 488, in _call_with_frames_removed
  File "/home/ubuntu/mypythonapp/app.py", line 1, in <module>
    from flask import Flask
ModuleNotFoundError: No module named 'flask'
[2025-02-13 10:47:40 +0000] [1752] [INFO] Worker exiting (pid: 1752)
[2025-02-13 10:47:40 +0000] [1629] [ERROR] Worker (pid:1752) exited with code 3
Traceback (most recent call last):
  File "/home/ubuntu/myenv/lib/python3.12/site-packages/gunicorn/arbiter.py", line 223, in run
  File "/home/ubuntu/myenv/lib/python3.12/site-packages/gunicorn/arbiter.py", line 256, in handle_term
StopIteration

During handling of the above exception, another exception occurred:

Traceback (most recent call last):
  File "/home/ubuntu/myenv/bin/gunicorn", line 8, in <module>
  File "/home/ubuntu/myenv/lib/python3.12/site-packages/gunicorn/app/wsgiapp.py", line 66, in run
  File "/home/ubuntu/myenv/lib/python3.12/site-packages/gunicorn/app/base.py", line 235, in run
  File "/home/ubuntu/myenv/lib/python3.12/site-packages/gunicorn/app/base.py", line 71, in run
  File "/home/ubuntu/myenv/lib/python3.12/site-packages/gunicorn/arbiter.py", line 226, in run
  File "/home/ubuntu/myenv/lib/python3.12/site-packages/gunicorn/arbiter.py", line 341, in halt
  File "/home/ubuntu/myenv/lib/python3.12/site-packages/gunicorn/arbiter.py", line 395, in stop
  File "/home/ubuntu/myenv/lib/python3.12/site-packages/gunicorn/arbiter.py", line 241, in handle_chld
  File "/home/ubuntu/myenv/lib/python3.12/site-packages/gunicorn/arbiter.py", line 529, in reap_workers
gunicorn.errors.HaltServer: <HaltServer 'Worker failed to boot.' 3>
